<?xml version="1.0" ?>
<!-- =================================================================================== -->
<!-- |    This document was autogenerated by xacro from robot_desc/mecabot_gz.main.xacro | -->
<!-- |    EDITING THIS FILE BY HAND IS NOT RECOMMENDED                                 | -->
<!-- =================================================================================== -->
<robot name="mecabot_gz" xmlns:gz="http://gazebosim.org/schema">
  <!-- MATERIALS -->
  <material name="grey">
    <color rgba="0.35 0.35 0.35 1"/>
  </material>
  <material name="silver">
    <color rgba="0.86 0.86 0.86 1"/>
  </material>
  <!-- BODY STARTS HERE -->
  <link name="base_link">
    <visual>
      <origin xyz="0 0 0.0525"/>
      <geometry>
        <box size="0.9 0.6 0.21"/>
      </geometry>
      <material name="silver"/>
    </visual>
    <collision>
      <origin xyz="0 0 0.0525"/>
      <geometry>
        <box size="0.9 0.6 0.21"/>
      </geometry>
    </collision>
    <inertial>
      <origin/>
      <mass value="0.5"/>
      <inertia ixx="0.0168375" ixy="0.0" ixz="0.0" iyy="0.0355875" iyz="0.0" izz="0.048749999999999995"/>
    </inertial>
  </link>
  <link name="front_left_mecanum_link">
    <visual>
      <origin xyz="0 0 0"/>
      <geometry>
        <mesh filename="file:///home/north/ros2-workspaces/mecabot_ws/install/mecabot_gz/share/mecabot_gz/../../../../robot_desc/mesh/mecanum_left.STL" scale="0.003 0.003 0.003"/>
        <!-- Scale mesh to radius -->
      </geometry>
      <material name="grey"/>
    </visual>
    <collision>
      <origin xyz="0 0 0"/>
      <geometry>
        <sphere radius="0.15"/>
      </geometry>
    </collision>
    <inertial>
      <!-- Values from Gazebo Harmonic mecanum_drive.sdf -->
      <mass value="2"/>
      <inertia ixx="0.145833" ixy="0" ixz="0" iyy="0.145833" iyz="0" izz="0.125"/>
    </inertial>
  </link>
  <gazebo reference="front_left_mecanum_link">
    <!-- NECESSARY: implemented this way to include the gz:expressed_in attributes-->
    <collision>
      <surface>
        <contact>
          <ode/>
        </contact>
        <friction>
          <ode>
            <mu>1.0</mu>
            <mu2>0.0</mu2>
            <fdir1 gz:expressed_in="base_link">1 -1 0</fdir1>
          </ode>
        </friction>
      </surface>
    </collision>
  </gazebo>
  <link name="front_right_mecanum_link">
    <visual>
      <origin xyz="0 0 0"/>
      <geometry>
        <mesh filename="file:///home/north/ros2-workspaces/mecabot_ws/install/mecabot_gz/share/mecabot_gz/../../../../robot_desc/mesh/mecanum_right.STL" scale="0.003 0.003 0.003"/>
        <!-- Scale mesh to radius -->
      </geometry>
      <material name="grey"/>
    </visual>
    <collision>
      <origin xyz="0 0 0"/>
      <geometry>
        <sphere radius="0.15"/>
      </geometry>
    </collision>
    <inertial>
      <!-- Values from Gazebo Harmonic mecanum_drive.sdf -->
      <mass value="2"/>
      <inertia ixx="0.145833" ixy="0" ixz="0" iyy="0.145833" iyz="0" izz="0.125"/>
    </inertial>
  </link>
  <gazebo reference="front_right_mecanum_link">
    <!-- NECESSARY: implemented this way to include the gz:expressed_in attributes-->
    <collision>
      <surface>
        <contact>
          <ode/>
        </contact>
        <friction>
          <ode>
            <mu>1.0</mu>
            <mu2>0.0</mu2>
            <fdir1 gz:expressed_in="base_link">1 1 0</fdir1>
          </ode>
        </friction>
      </surface>
    </collision>
  </gazebo>
  <link name="rear_right_mecanum_link">
    <visual>
      <origin xyz="0 0 0"/>
      <geometry>
        <mesh filename="file:///home/north/ros2-workspaces/mecabot_ws/install/mecabot_gz/share/mecabot_gz/../../../../robot_desc/mesh/mecanum_left.STL" scale="0.003 0.003 0.003"/>
        <!-- Scale mesh to radius -->
      </geometry>
      <material name="grey"/>
    </visual>
    <collision>
      <origin xyz="0 0 0"/>
      <geometry>
        <sphere radius="0.15"/>
      </geometry>
    </collision>
    <inertial>
      <!-- Values from Gazebo Harmonic mecanum_drive.sdf -->
      <mass value="2"/>
      <inertia ixx="0.145833" ixy="0" ixz="0" iyy="0.145833" iyz="0" izz="0.125"/>
    </inertial>
  </link>
  <gazebo reference="rear_right_mecanum_link">
    <!-- NECESSARY: implemented this way to include the gz:expressed_in attributes-->
    <collision>
      <surface>
        <contact>
          <ode/>
        </contact>
        <friction>
          <ode>
            <mu>1.0</mu>
            <mu2>0.0</mu2>
            <fdir1 gz:expressed_in="base_link">1 -1 0</fdir1>
          </ode>
        </friction>
      </surface>
    </collision>
  </gazebo>
  <link name="rear_left_mecanum_link">
    <visual>
      <origin xyz="0 0 0"/>
      <geometry>
        <mesh filename="file:///home/north/ros2-workspaces/mecabot_ws/install/mecabot_gz/share/mecabot_gz/../../../../robot_desc/mesh/mecanum_right.STL" scale="0.003 0.003 0.003"/>
        <!-- Scale mesh to radius -->
      </geometry>
      <material name="grey"/>
    </visual>
    <collision>
      <origin xyz="0 0 0"/>
      <geometry>
        <sphere radius="0.15"/>
      </geometry>
    </collision>
    <inertial>
      <!-- Values from Gazebo Harmonic mecanum_drive.sdf -->
      <mass value="2"/>
      <inertia ixx="0.145833" ixy="0" ixz="0" iyy="0.145833" iyz="0" izz="0.125"/>
    </inertial>
  </link>
  <gazebo reference="rear_left_mecanum_link">
    <!-- NECESSARY: implemented this way to include the gz:expressed_in attributes-->
    <collision>
      <surface>
        <contact>
          <ode/>
        </contact>
        <friction>
          <ode>
            <mu>1.0</mu>
            <mu2>0.0</mu2>
            <fdir1 gz:expressed_in="base_link">1 1 0</fdir1>
          </ode>
        </friction>
      </surface>
    </collision>
  </gazebo>
  <link name="test_link">
    <visual>
      <origin rpy="1.5707963267948966 0 0" xyz="0 0.5 0"/>
      <geometry>
        <mesh filename="file:///home/north/ros2-workspaces/mecabot_ws/install/mecabot_gz/share/mecabot_gz/../../../../robot_desc/mesh/omni_wheel.stl" scale="0.035 0.035 0.035"/>
        <!-- Scale mesh to radius -->
      </geometry>
      <material name="grey"/>
    </visual>
    <collision>
      <origin xyz="0 0 0"/>
      <geometry>
        <sphere radius="0.15"/>
      </geometry>
    </collision>
    <inertial>
      <!-- 
          Values referenced from Gazebo Harmonic mecanum_drive.sdf 
          but the mass changed from 2kg to 1.5kg
        -->
      <mass value="1.5"/>
      <inertia ixx="0.109375" ixy="0" ixz="0" iyy="0.109375" iyz="0" izz="0.09375"/>
    </inertial>
  </link>
  <gazebo reference="test_link">
    <!-- NECESSARY: implemented this way to include the gz:expressed_in attributes-->
    <collision>
      <surface>
        <contact>
          <ode/>
        </contact>
        <friction>
          <ode>
            <mu>1.0</mu>
            <mu2>0.0</mu2>
            <fdir1 gz:expressed_in="base_link">1 0 0</fdir1>
          </ode>
        </friction>
      </surface>
    </collision>
  </gazebo>
  <joint name="test" type="fixed">
    <parent link="base_link"/>
    <child link="test_link"/>
  </joint>
  <joint name="front_left_mecanum_joint" type="continuous">
    <origin xyz="0.28125 0.375 0"/>
    <parent link="base_link"/>
    <child link="front_left_mecanum_link"/>
    <axis xyz="0 1 0"/>
  </joint>
  <joint name="front_right_mecanum_joint" type="continuous">
    <origin xyz="0.28125 -0.375 0"/>
    <parent link="base_link"/>
    <child link="front_right_mecanum_link"/>
    <axis xyz="0 1 0"/>
  </joint>
  <joint name="rear_right_mecanum_joint" type="continuous">
    <origin xyz="-0.28125 -0.375 0"/>
    <parent link="base_link"/>
    <child link="rear_right_mecanum_link"/>
    <axis xyz="0 1 0"/>
  </joint>
  <joint name="rear_left_mecanum_joint" type="continuous">
    <origin xyz="-0.28125 0.375 0"/>
    <parent link="base_link"/>
    <child link="rear_left_mecanum_link"/>
    <axis xyz="0 1 0"/>
  </joint>
  <!-- GAZEBO PLUGINS -->
  <gazebo>
    <plugin filename="gz-sim-mecanum-drive-system" name="gz::sim::systems::MecanumDrive">
      <front_left_joint>front_left_mecanum_joint</front_left_joint>
      <front_right_joint>front_right_mecanum_joint</front_right_joint>
      <back_left_joint>rear_left_mecanum_joint</back_left_joint>
      <back_right_joint>rear_right_mecanum_joint</back_right_joint>
      <wheel_separation>0.75</wheel_separation>
      <wheelbase>0.5625</wheelbase>
      <wheel_radius>0.15</wheel_radius>
      <topic>/cmd_vel</topic>
      <min_acceleration>-3</min_acceleration>
      <max_acceleration>3</max_acceleration>
    </plugin>
    <plugin filename="gz-sim-joint-state-publisher-system" name="gz::sim::systems::JointStatePublisher">
      <topic>/joint_states</topic>
    </plugin>
  </gazebo>
</robot>
